[2023-07-16 00:00:12,118] {taskinstance.py:1179} INFO - Dependencies all met for <TaskInstance: probando_conexion.primera_tarea manual__2023-07-15T23:54:05.001968+00:00 [queued]>
[2023-07-16 00:00:12,137] {taskinstance.py:1179} INFO - Dependencies all met for <TaskInstance: probando_conexion.primera_tarea manual__2023-07-15T23:54:05.001968+00:00 [queued]>
[2023-07-16 00:00:12,137] {taskinstance.py:1376} INFO - 
--------------------------------------------------------------------------------
[2023-07-16 00:00:12,137] {taskinstance.py:1377} INFO - Starting attempt 4 of 11
[2023-07-16 00:00:12,138] {taskinstance.py:1378} INFO - 
--------------------------------------------------------------------------------
[2023-07-16 00:00:12,161] {taskinstance.py:1397} INFO - Executing <Task(PythonOperator): primera_tarea> on 2023-07-15 23:54:05.001968+00:00
[2023-07-16 00:00:12,167] {standard_task_runner.py:52} INFO - Started process 5160 to run task
[2023-07-16 00:00:12,172] {standard_task_runner.py:79} INFO - Running: ['***', 'tasks', 'run', 'probando_conexion', 'primera_tarea', 'manual__2023-07-15T23:54:05.001968+00:00', '--job-id', '843', '--raw', '--subdir', 'DAGS_FOLDER/variables_y_secrets.py', '--cfg-path', '/tmp/tmp5wpb7pop', '--error-file', '/tmp/tmpttqcw0fj']
[2023-07-16 00:00:12,173] {standard_task_runner.py:80} INFO - Job 843: Subtask primera_tarea
[2023-07-16 00:00:12,266] {task_command.py:371} INFO - Running <TaskInstance: probando_conexion.primera_tarea manual__2023-07-15T23:54:05.001968+00:00 [running]> on host 7a1b6d75866e
[2023-07-16 00:00:12,379] {taskinstance.py:1591} INFO - Exporting the following env vars:
AIRFLOW_CTX_DAG_EMAIL=arielmfeldman.af@gmail.com
AIRFLOW_CTX_DAG_OWNER=Ariel Feldman
AIRFLOW_CTX_DAG_ID=probando_conexion
AIRFLOW_CTX_TASK_ID=primera_tarea
AIRFLOW_CTX_EXECUTION_DATE=2023-07-15T23:54:05.001968+00:00
AIRFLOW_CTX_TRY_NUMBER=4
AIRFLOW_CTX_DAG_RUN_ID=manual__2023-07-15T23:54:05.001968+00:00
[2023-07-16 00:00:12,381] {taskinstance.py:1909} ERROR - Task failed with exception
Traceback (most recent call last):
  File "/home/airflow/.local/lib/python3.7/site-packages/airflow/operators/python.py", line 171, in execute
    return_value = self.execute_callable()
  File "/home/airflow/.local/lib/python3.7/site-packages/airflow/operators/python.py", line 189, in execute_callable
    return self.python_callable(*self.op_args, **self.op_kwargs)
  File "/opt/airflow/dags/variables_y_secrets.py", line 8, in print_message
    print(SECRET_API_KEY_PUBLIC)
NameError: name 'SECRET_API_KEY_PUBLIC' is not defined
[2023-07-16 00:00:12,394] {taskinstance.py:1420} INFO - Marking task as UP_FOR_RETRY. dag_id=probando_conexion, task_id=primera_tarea, execution_date=20230715T235405, start_date=20230716T000012, end_date=20230716T000012
[2023-07-16 00:00:12,416] {warnings.py:110} WARNING - /home/***/.local/lib/python3.7/site-packages/***/utils/email.py:119: PendingDeprecationWarning: Fetching SMTP credentials from configuration variables will be deprecated in a future release. Please set credentials using a connection instead.
  send_mime_email(e_from=mail_from, e_to=recipients, mime_msg=msg, conn_id=conn_id, dryrun=dryrun)

[2023-07-16 00:00:12,416] {configuration.py:552} WARNING - section/key [smtp/smtp_user] not found in config
[2023-07-16 00:00:12,417] {email.py:228} INFO - Email alerting: attempt 1
[2023-07-16 00:00:12,428] {configuration.py:552} WARNING - section/key [smtp/smtp_user] not found in config
[2023-07-16 00:00:12,428] {email.py:228} INFO - Email alerting: attempt 1
[2023-07-16 00:00:12,429] {taskinstance.py:1964} ERROR - Failed to send email to: ['arielmfeldman.af@gmail.com']
Traceback (most recent call last):
  File "/home/airflow/.local/lib/python3.7/site-packages/airflow/models/taskinstance.py", line 1471, in _run_raw_task
    self._execute_task_with_callbacks(context, test_mode)
  File "/home/airflow/.local/lib/python3.7/site-packages/airflow/models/taskinstance.py", line 1618, in _execute_task_with_callbacks
    result = self._execute_task(context, task_orig)
  File "/home/airflow/.local/lib/python3.7/site-packages/airflow/models/taskinstance.py", line 1679, in _execute_task
    result = execute_callable(context=context)
  File "/home/airflow/.local/lib/python3.7/site-packages/airflow/operators/python.py", line 171, in execute
    return_value = self.execute_callable()
  File "/home/airflow/.local/lib/python3.7/site-packages/airflow/operators/python.py", line 189, in execute_callable
    return self.python_callable(*self.op_args, **self.op_kwargs)
  File "/opt/airflow/dags/variables_y_secrets.py", line 8, in print_message
    print(SECRET_API_KEY_PUBLIC)
NameError: name 'SECRET_API_KEY_PUBLIC' is not defined

During handling of the above exception, another exception occurred:

Traceback (most recent call last):
  File "/home/airflow/.local/lib/python3.7/site-packages/airflow/models/taskinstance.py", line 2346, in email_alert
    send_email(task.email, subject, html_content)
  File "/home/airflow/.local/lib/python3.7/site-packages/airflow/utils/email.py", line 71, in send_email
    **kwargs,
  File "/home/airflow/.local/lib/python3.7/site-packages/airflow/utils/email.py", line 119, in send_email_smtp
    send_mime_email(e_from=mail_from, e_to=recipients, mime_msg=msg, conn_id=conn_id, dryrun=dryrun)
  File "/home/airflow/.local/lib/python3.7/site-packages/airflow/utils/email.py", line 230, in send_mime_email
    smtp_conn = _get_smtp_connection(smtp_host, smtp_port, smtp_timeout, smtp_ssl)
  File "/home/airflow/.local/lib/python3.7/site-packages/airflow/utils/email.py", line 264, in _get_smtp_connection
    else smtplib.SMTP(host=host, port=port, timeout=timeout)
  File "/usr/local/lib/python3.7/smtplib.py", line 251, in __init__
    (code, msg) = self.connect(host, port)
  File "/usr/local/lib/python3.7/smtplib.py", line 336, in connect
    self.sock = self._get_socket(host, port, self.timeout)
  File "/usr/local/lib/python3.7/smtplib.py", line 307, in _get_socket
    self.source_address)
  File "/usr/local/lib/python3.7/socket.py", line 728, in create_connection
    raise err
  File "/usr/local/lib/python3.7/socket.py", line 716, in create_connection
    sock.connect(sa)
OSError: [Errno 99] Cannot assign requested address

During handling of the above exception, another exception occurred:

Traceback (most recent call last):
  File "/home/airflow/.local/lib/python3.7/site-packages/airflow/models/taskinstance.py", line 1962, in handle_failure
    self.email_alert(error, task)
  File "/home/airflow/.local/lib/python3.7/site-packages/airflow/models/taskinstance.py", line 2348, in email_alert
    send_email(task.email, subject, html_content_err)
  File "/home/airflow/.local/lib/python3.7/site-packages/airflow/utils/email.py", line 71, in send_email
    **kwargs,
  File "/home/airflow/.local/lib/python3.7/site-packages/airflow/utils/email.py", line 119, in send_email_smtp
    send_mime_email(e_from=mail_from, e_to=recipients, mime_msg=msg, conn_id=conn_id, dryrun=dryrun)
  File "/home/airflow/.local/lib/python3.7/site-packages/airflow/utils/email.py", line 230, in send_mime_email
    smtp_conn = _get_smtp_connection(smtp_host, smtp_port, smtp_timeout, smtp_ssl)
  File "/home/airflow/.local/lib/python3.7/site-packages/airflow/utils/email.py", line 264, in _get_smtp_connection
    else smtplib.SMTP(host=host, port=port, timeout=timeout)
  File "/usr/local/lib/python3.7/smtplib.py", line 251, in __init__
    (code, msg) = self.connect(host, port)
  File "/usr/local/lib/python3.7/smtplib.py", line 336, in connect
    self.sock = self._get_socket(host, port, self.timeout)
  File "/usr/local/lib/python3.7/smtplib.py", line 307, in _get_socket
    self.source_address)
  File "/usr/local/lib/python3.7/socket.py", line 728, in create_connection
    raise err
  File "/usr/local/lib/python3.7/socket.py", line 716, in create_connection
    sock.connect(sa)
OSError: [Errno 99] Cannot assign requested address
[2023-07-16 00:00:12,448] {standard_task_runner.py:97} ERROR - Failed to execute job 843 for task primera_tarea (name 'SECRET_API_KEY_PUBLIC' is not defined; 5160)
[2023-07-16 00:00:12,464] {local_task_job.py:156} INFO - Task exited with return code 1
[2023-07-16 00:00:12,552] {local_task_job.py:273} INFO - 0 downstream tasks scheduled from follow-on schedule check
