[2023-08-01 20:40:12,400] {taskinstance.py:1179} INFO - Dependencies all met for <TaskInstance: etl_api_marvel_hacia_aws_redshift_multitask.cargar_data scheduled__2023-08-01T20:31:41.077320+00:00 [queued]>
[2023-08-01 20:40:12,480] {taskinstance.py:1179} INFO - Dependencies all met for <TaskInstance: etl_api_marvel_hacia_aws_redshift_multitask.cargar_data scheduled__2023-08-01T20:31:41.077320+00:00 [queued]>
[2023-08-01 20:40:12,480] {taskinstance.py:1376} INFO - 
--------------------------------------------------------------------------------
[2023-08-01 20:40:12,480] {taskinstance.py:1377} INFO - Starting attempt 4 of 11
[2023-08-01 20:40:12,480] {taskinstance.py:1378} INFO - 
--------------------------------------------------------------------------------
[2023-08-01 20:40:12,587] {taskinstance.py:1397} INFO - Executing <Task(PythonOperator): cargar_data> on 2023-08-01 20:31:41.077320+00:00
[2023-08-01 20:40:12,597] {standard_task_runner.py:52} INFO - Started process 12245 to run task
[2023-08-01 20:40:12,608] {standard_task_runner.py:79} INFO - Running: ['***', 'tasks', 'run', 'etl_api_marvel_hacia_aws_redshift_multitask', 'cargar_data', 'scheduled__2023-08-01T20:31:41.077320+00:00', '--job-id', '1085', '--raw', '--subdir', 'DAGS_FOLDER/dag_etl_multiple_tasks.py', '--cfg-path', '/tmp/tmp9xojxd92', '--error-file', '/tmp/tmps2b2u1yw']
[2023-08-01 20:40:12,610] {standard_task_runner.py:80} INFO - Job 1085: Subtask cargar_data
[2023-08-01 20:40:13,191] {task_command.py:371} INFO - Running <TaskInstance: etl_api_marvel_hacia_aws_redshift_multitask.cargar_data scheduled__2023-08-01T20:31:41.077320+00:00 [running]> on host 24cbf2f01ed0
[2023-08-01 20:40:13,740] {taskinstance.py:1591} INFO - Exporting the following env vars:
AIRFLOW_CTX_DAG_EMAIL=arielmfeldman.af@gmail.com
AIRFLOW_CTX_DAG_OWNER=Ariel Feldman
AIRFLOW_CTX_DAG_ID=etl_api_marvel_hacia_aws_redshift_multitask
AIRFLOW_CTX_TASK_ID=cargar_data
AIRFLOW_CTX_EXECUTION_DATE=2023-08-01T20:31:41.077320+00:00
AIRFLOW_CTX_TRY_NUMBER=4
AIRFLOW_CTX_DAG_RUN_ID=scheduled__2023-08-01T20:31:41.077320+00:00
[2023-08-01 20:40:16,050] {taskinstance.py:1909} ERROR - Task failed with exception
Traceback (most recent call last):
  File "/home/airflow/.local/lib/python3.7/site-packages/redshift_connector/core.py", line 1631, in execute
    ps = cache["ps"][key]
KeyError: ('\n            CREATE TABLE IF NOT EXISTS arielmfeldman_coderhouse.marvelCharacters(\n                id_character int not null,\n                nombre varchar(50) not null,\n                descripcion varchar(255) null,\n                cantidad_de_comics integer,\n                cantidad_de_series integer,\n                cantidad_de_historias integer,\n                fecha_modificacion date,\n                fecha_insercion_bd double\n            )\n            distkey(id_character)\n            sortkey(id_character,fecha_insercion_bd);\n    ', ())

During handling of the above exception, another exception occurred:

Traceback (most recent call last):
  File "/home/airflow/.local/lib/python3.7/site-packages/airflow/operators/python.py", line 171, in execute
    return_value = self.execute_callable()
  File "/home/airflow/.local/lib/python3.7/site-packages/airflow/operators/python.py", line 189, in execute_callable
    return self.python_callable(*self.op_args, **self.op_kwargs)
  File "/opt/airflow/dags/dag_etl_multiple_tasks.py", line 237, in load_data
    cursor.execute(create_table)
  File "/home/airflow/.local/lib/python3.7/site-packages/redshift_connector/cursor.py", line 240, in execute
    self._c.execute(self, operation, args)
  File "/home/airflow/.local/lib/python3.7/site-packages/redshift_connector/core.py", line 1701, in execute
    self.handle_messages(cursor)
  File "/home/airflow/.local/lib/python3.7/site-packages/redshift_connector/core.py", line 1969, in handle_messages
    raise self.error
redshift_connector.error.ProgrammingError: {'S': 'ERROR', 'C': '42704', 'M': 'type "double" does not exist', 'F': '../src/pg/src/backend/parser/parse_type.c', 'L': '215', 'R': 'typenameType'}
[2023-08-01 20:40:16,067] {taskinstance.py:1420} INFO - Marking task as UP_FOR_RETRY. dag_id=etl_api_marvel_hacia_aws_redshift_multitask, task_id=cargar_data, execution_date=20230801T203141, start_date=20230801T204012, end_date=20230801T204016
[2023-08-01 20:40:16,100] {warnings.py:110} WARNING - /home/***/.local/lib/python3.7/site-packages/***/utils/email.py:119: PendingDeprecationWarning: Fetching SMTP credentials from configuration variables will be deprecated in a future release. Please set credentials using a connection instead.
  send_mime_email(e_from=mail_from, e_to=recipients, mime_msg=msg, conn_id=conn_id, dryrun=dryrun)

[2023-08-01 20:40:16,100] {configuration.py:552} WARNING - section/key [smtp/smtp_user] not found in config
[2023-08-01 20:40:16,100] {email.py:228} INFO - Email alerting: attempt 1
[2023-08-01 20:40:16,111] {configuration.py:552} WARNING - section/key [smtp/smtp_user] not found in config
[2023-08-01 20:40:16,111] {email.py:228} INFO - Email alerting: attempt 1
[2023-08-01 20:40:16,113] {taskinstance.py:1964} ERROR - Failed to send email to: ['arielmfeldman.af@gmail.com']
Traceback (most recent call last):
  File "/home/airflow/.local/lib/python3.7/site-packages/redshift_connector/core.py", line 1631, in execute
    ps = cache["ps"][key]
KeyError: ('\n            CREATE TABLE IF NOT EXISTS arielmfeldman_coderhouse.marvelCharacters(\n                id_character int not null,\n                nombre varchar(50) not null,\n                descripcion varchar(255) null,\n                cantidad_de_comics integer,\n                cantidad_de_series integer,\n                cantidad_de_historias integer,\n                fecha_modificacion date,\n                fecha_insercion_bd double\n            )\n            distkey(id_character)\n            sortkey(id_character,fecha_insercion_bd);\n    ', ())

During handling of the above exception, another exception occurred:

Traceback (most recent call last):
  File "/home/airflow/.local/lib/python3.7/site-packages/airflow/models/taskinstance.py", line 1471, in _run_raw_task
    self._execute_task_with_callbacks(context, test_mode)
  File "/home/airflow/.local/lib/python3.7/site-packages/airflow/models/taskinstance.py", line 1618, in _execute_task_with_callbacks
    result = self._execute_task(context, task_orig)
  File "/home/airflow/.local/lib/python3.7/site-packages/airflow/models/taskinstance.py", line 1679, in _execute_task
    result = execute_callable(context=context)
  File "/home/airflow/.local/lib/python3.7/site-packages/airflow/operators/python.py", line 171, in execute
    return_value = self.execute_callable()
  File "/home/airflow/.local/lib/python3.7/site-packages/airflow/operators/python.py", line 189, in execute_callable
    return self.python_callable(*self.op_args, **self.op_kwargs)
  File "/opt/airflow/dags/dag_etl_multiple_tasks.py", line 237, in load_data
    cursor.execute(create_table)
  File "/home/airflow/.local/lib/python3.7/site-packages/redshift_connector/cursor.py", line 240, in execute
    self._c.execute(self, operation, args)
  File "/home/airflow/.local/lib/python3.7/site-packages/redshift_connector/core.py", line 1701, in execute
    self.handle_messages(cursor)
  File "/home/airflow/.local/lib/python3.7/site-packages/redshift_connector/core.py", line 1969, in handle_messages
    raise self.error
redshift_connector.error.ProgrammingError: {'S': 'ERROR', 'C': '42704', 'M': 'type "double" does not exist', 'F': '../src/pg/src/backend/parser/parse_type.c', 'L': '215', 'R': 'typenameType'}

During handling of the above exception, another exception occurred:

Traceback (most recent call last):
  File "/home/airflow/.local/lib/python3.7/site-packages/airflow/models/taskinstance.py", line 2346, in email_alert
    send_email(task.email, subject, html_content)
  File "/home/airflow/.local/lib/python3.7/site-packages/airflow/utils/email.py", line 71, in send_email
    **kwargs,
  File "/home/airflow/.local/lib/python3.7/site-packages/airflow/utils/email.py", line 119, in send_email_smtp
    send_mime_email(e_from=mail_from, e_to=recipients, mime_msg=msg, conn_id=conn_id, dryrun=dryrun)
  File "/home/airflow/.local/lib/python3.7/site-packages/airflow/utils/email.py", line 230, in send_mime_email
    smtp_conn = _get_smtp_connection(smtp_host, smtp_port, smtp_timeout, smtp_ssl)
  File "/home/airflow/.local/lib/python3.7/site-packages/airflow/utils/email.py", line 264, in _get_smtp_connection
    else smtplib.SMTP(host=host, port=port, timeout=timeout)
  File "/usr/local/lib/python3.7/smtplib.py", line 251, in __init__
    (code, msg) = self.connect(host, port)
  File "/usr/local/lib/python3.7/smtplib.py", line 336, in connect
    self.sock = self._get_socket(host, port, self.timeout)
  File "/usr/local/lib/python3.7/smtplib.py", line 307, in _get_socket
    self.source_address)
  File "/usr/local/lib/python3.7/socket.py", line 728, in create_connection
    raise err
  File "/usr/local/lib/python3.7/socket.py", line 716, in create_connection
    sock.connect(sa)
OSError: [Errno 99] Cannot assign requested address

During handling of the above exception, another exception occurred:

Traceback (most recent call last):
  File "/home/airflow/.local/lib/python3.7/site-packages/airflow/models/taskinstance.py", line 1962, in handle_failure
    self.email_alert(error, task)
  File "/home/airflow/.local/lib/python3.7/site-packages/airflow/models/taskinstance.py", line 2348, in email_alert
    send_email(task.email, subject, html_content_err)
  File "/home/airflow/.local/lib/python3.7/site-packages/airflow/utils/email.py", line 71, in send_email
    **kwargs,
  File "/home/airflow/.local/lib/python3.7/site-packages/airflow/utils/email.py", line 119, in send_email_smtp
    send_mime_email(e_from=mail_from, e_to=recipients, mime_msg=msg, conn_id=conn_id, dryrun=dryrun)
  File "/home/airflow/.local/lib/python3.7/site-packages/airflow/utils/email.py", line 230, in send_mime_email
    smtp_conn = _get_smtp_connection(smtp_host, smtp_port, smtp_timeout, smtp_ssl)
  File "/home/airflow/.local/lib/python3.7/site-packages/airflow/utils/email.py", line 264, in _get_smtp_connection
    else smtplib.SMTP(host=host, port=port, timeout=timeout)
  File "/usr/local/lib/python3.7/smtplib.py", line 251, in __init__
    (code, msg) = self.connect(host, port)
  File "/usr/local/lib/python3.7/smtplib.py", line 336, in connect
    self.sock = self._get_socket(host, port, self.timeout)
  File "/usr/local/lib/python3.7/smtplib.py", line 307, in _get_socket
    self.source_address)
  File "/usr/local/lib/python3.7/socket.py", line 728, in create_connection
    raise err
  File "/usr/local/lib/python3.7/socket.py", line 716, in create_connection
    sock.connect(sa)
OSError: [Errno 99] Cannot assign requested address
[2023-08-01 20:40:16,184] {standard_task_runner.py:97} ERROR - Failed to execute job 1085 for task cargar_data ({'S': 'ERROR', 'C': '42704', 'M': 'type "double" does not exist', 'F': '../src/pg/src/backend/parser/parse_type.c', 'L': '215', 'R': 'typenameType'}; 12245)
[2023-08-01 20:40:16,231] {local_task_job.py:156} INFO - Task exited with return code 1
[2023-08-01 20:40:16,391] {local_task_job.py:273} INFO - 0 downstream tasks scheduled from follow-on schedule check
