[2023-07-14 02:50:53,342] {taskinstance.py:1179} INFO - Dependencies all met for <TaskInstance: data_sensor_id.sensar_archivo manual__2023-07-14T02:50:52.196829+00:00 [queued]>
[2023-07-14 02:50:53,366] {taskinstance.py:1179} INFO - Dependencies all met for <TaskInstance: data_sensor_id.sensar_archivo manual__2023-07-14T02:50:52.196829+00:00 [queued]>
[2023-07-14 02:50:53,366] {taskinstance.py:1376} INFO - 
--------------------------------------------------------------------------------
[2023-07-14 02:50:53,366] {taskinstance.py:1377} INFO - Starting attempt 1 of 1
[2023-07-14 02:50:53,366] {taskinstance.py:1378} INFO - 
--------------------------------------------------------------------------------
[2023-07-14 02:50:53,412] {taskinstance.py:1397} INFO - Executing <Task(FileSensor): sensar_archivo> on 2023-07-14 02:50:52.196829+00:00
[2023-07-14 02:50:53,423] {standard_task_runner.py:52} INFO - Started process 5359 to run task
[2023-07-14 02:50:53,432] {standard_task_runner.py:79} INFO - Running: ['***', 'tasks', 'run', 'data_sensor_id', 'sensar_archivo', 'manual__2023-07-14T02:50:52.196829+00:00', '--job-id', '829', '--raw', '--subdir', 'DAGS_FOLDER/first_sensor.py', '--cfg-path', '/tmp/tmprng4pqyy', '--error-file', '/tmp/tmp4fll22yn']
[2023-07-14 02:50:53,432] {standard_task_runner.py:80} INFO - Job 829: Subtask sensar_archivo
[2023-07-14 02:50:53,546] {task_command.py:371} INFO - Running <TaskInstance: data_sensor_id.sensar_archivo manual__2023-07-14T02:50:52.196829+00:00 [running]> on host 7a1b6d75866e
[2023-07-14 02:50:53,668] {taskinstance.py:1591} INFO - Exporting the following env vars:
AIRFLOW_CTX_DAG_OWNER=***
AIRFLOW_CTX_DAG_ID=data_sensor_id
AIRFLOW_CTX_TASK_ID=sensar_archivo
AIRFLOW_CTX_EXECUTION_DATE=2023-07-14T02:50:52.196829+00:00
AIRFLOW_CTX_TRY_NUMBER=1
AIRFLOW_CTX_DAG_RUN_ID=manual__2023-07-14T02:50:52.196829+00:00
[2023-07-14 02:50:53,712] {taskinstance.py:1909} ERROR - Task failed with exception
Traceback (most recent call last):
  File "/home/airflow/.local/lib/python3.7/site-packages/airflow/sensors/base.py", line 277, in execute
    poke_return = self.poke(context)
  File "/home/airflow/.local/lib/python3.7/site-packages/airflow/sensors/filesystem.py", line 55, in poke
    hook = FSHook(self.fs_conn_id)
  File "/home/airflow/.local/lib/python3.7/site-packages/airflow/hooks/filesystem.py", line 38, in __init__
    conn = self.get_connection(conn_id)
  File "/home/airflow/.local/lib/python3.7/site-packages/airflow/hooks/base.py", line 67, in get_connection
    conn = Connection.get_connection_from_secrets(conn_id)
  File "/home/airflow/.local/lib/python3.7/site-packages/airflow/models/connection.py", line 430, in get_connection_from_secrets
    raise AirflowNotFoundException(f"The conn_id `{conn_id}` isn't defined")
airflow.exceptions.AirflowNotFoundException: The conn_id `fs_default` isn't defined
[2023-07-14 02:50:53,718] {taskinstance.py:1420} INFO - Marking task as FAILED. dag_id=data_sensor_id, task_id=sensar_archivo, execution_date=20230714T025052, start_date=20230714T025053, end_date=20230714T025053
[2023-07-14 02:50:53,732] {standard_task_runner.py:97} ERROR - Failed to execute job 829 for task sensar_archivo (The conn_id `fs_default` isn't defined; 5359)
[2023-07-14 02:50:53,776] {local_task_job.py:156} INFO - Task exited with return code 1
[2023-07-14 02:50:53,863] {local_task_job.py:273} INFO - 0 downstream tasks scheduled from follow-on schedule check
