[2023-08-01 22:29:31,546] {taskinstance.py:1179} INFO - Dependencies all met for <TaskInstance: etl_api_marvel_hacia_aws_redshift_multitask_failure.extraer_data manual__2023-08-01T22:29:29.691699+00:00 [queued]>
[2023-08-01 22:29:31,560] {taskinstance.py:1179} INFO - Dependencies all met for <TaskInstance: etl_api_marvel_hacia_aws_redshift_multitask_failure.extraer_data manual__2023-08-01T22:29:29.691699+00:00 [queued]>
[2023-08-01 22:29:31,560] {taskinstance.py:1376} INFO - 
--------------------------------------------------------------------------------
[2023-08-01 22:29:31,560] {taskinstance.py:1377} INFO - Starting attempt 1 of 2
[2023-08-01 22:29:31,560] {taskinstance.py:1378} INFO - 
--------------------------------------------------------------------------------
[2023-08-01 22:29:31,581] {taskinstance.py:1397} INFO - Executing <Task(PythonOperator): extraer_data> on 2023-08-01 22:29:29.691699+00:00
[2023-08-01 22:29:31,589] {standard_task_runner.py:52} INFO - Started process 4079 to run task
[2023-08-01 22:29:31,593] {standard_task_runner.py:79} INFO - Running: ['***', 'tasks', 'run', 'etl_api_marvel_hacia_aws_redshift_multitask_failure', 'extraer_data', 'manual__2023-08-01T22:29:29.691699+00:00', '--job-id', '1227', '--raw', '--subdir', 'DAGS_FOLDER/dag_etl_multiple_tasks_failure.py', '--cfg-path', '/tmp/tmp5n3523p1', '--error-file', '/tmp/tmp_o239u7_']
[2023-08-01 22:29:31,595] {standard_task_runner.py:80} INFO - Job 1227: Subtask extraer_data
[2023-08-01 22:29:31,684] {task_command.py:371} INFO - Running <TaskInstance: etl_api_marvel_hacia_aws_redshift_multitask_failure.extraer_data manual__2023-08-01T22:29:29.691699+00:00 [running]> on host 24cbf2f01ed0
[2023-08-01 22:29:31,779] {taskinstance.py:1591} INFO - Exporting the following env vars:
AIRFLOW_CTX_DAG_EMAIL=arielmfeldman.af@gmail.com
AIRFLOW_CTX_DAG_OWNER=Ariel Feldman
AIRFLOW_CTX_DAG_ID=etl_api_marvel_hacia_aws_redshift_multitask_failure
AIRFLOW_CTX_TASK_ID=extraer_data
AIRFLOW_CTX_EXECUTION_DATE=2023-08-01T22:29:29.691699+00:00
AIRFLOW_CTX_TRY_NUMBER=1
AIRFLOW_CTX_DAG_RUN_ID=manual__2023-08-01T22:29:29.691699+00:00
[2023-08-01 22:29:32,910] {python.py:173} INFO - Done. Returned value was: None
[2023-08-01 22:29:32,927] {taskinstance.py:1420} INFO - Marking task as SUCCESS. dag_id=etl_api_marvel_hacia_aws_redshift_multitask_failure, task_id=extraer_data, execution_date=20230801T222929, start_date=20230801T222931, end_date=20230801T222932
[2023-08-01 22:29:32,969] {local_task_job.py:156} INFO - Task exited with return code 0
[2023-08-01 22:29:35,537] {taskinstance.py:1760} ERROR - Error when executing on_success_callback
Traceback (most recent call last):
  File "/home/airflow/.local/lib/python3.7/site-packages/airflow/models/taskinstance.py", line 1758, in _run_finished_callback
    task.on_success_callback(context)
  File "/opt/airflow/dags/dag_etl_multiple_tasks_failure.py", line 150, in send_mail_success
    msg=message,
  File "/usr/local/lib/python3.7/smtplib.py", line 887, in sendmail
    (code, resp) = self.data(msg)
  File "/usr/local/lib/python3.7/smtplib.py", line 569, in data
    q = _quote_periods(msg)
  File "/usr/local/lib/python3.7/smtplib.py", line 176, in _quote_periods
    return re.sub(br'(?m)^\.', b'..', bindata)
  File "/usr/local/lib/python3.7/re.py", line 194, in sub
    return _compile(pattern, flags).sub(repl, string, count)
TypeError: expected string or bytes-like object
[2023-08-01 22:29:35,564] {local_task_job.py:273} INFO - 0 downstream tasks scheduled from follow-on schedule check
