[2023-07-16 02:50:08,666] {taskinstance.py:1179} INFO - Dependencies all met for <TaskInstance: etl_api_marvel_hacia_aws_redshift_multitask.cargar_data manual__2023-07-16T02:50:00.771021+00:00 [queued]>
[2023-07-16 02:50:08,681] {taskinstance.py:1179} INFO - Dependencies all met for <TaskInstance: etl_api_marvel_hacia_aws_redshift_multitask.cargar_data manual__2023-07-16T02:50:00.771021+00:00 [queued]>
[2023-07-16 02:50:08,681] {taskinstance.py:1376} INFO - 
--------------------------------------------------------------------------------
[2023-07-16 02:50:08,681] {taskinstance.py:1377} INFO - Starting attempt 1 of 11
[2023-07-16 02:50:08,681] {taskinstance.py:1378} INFO - 
--------------------------------------------------------------------------------
[2023-07-16 02:50:08,702] {taskinstance.py:1397} INFO - Executing <Task(PythonOperator): cargar_data> on 2023-07-16 02:50:00.771021+00:00
[2023-07-16 02:50:08,710] {standard_task_runner.py:52} INFO - Started process 10622 to run task
[2023-07-16 02:50:08,714] {standard_task_runner.py:79} INFO - Running: ['***', 'tasks', 'run', 'etl_api_marvel_hacia_aws_redshift_multitask', 'cargar_data', 'manual__2023-07-16T02:50:00.771021+00:00', '--job-id', '897', '--raw', '--subdir', 'DAGS_FOLDER/dag_etl_multiple_tasks.py', '--cfg-path', '/tmp/tmpivx5glod', '--error-file', '/tmp/tmpmktoxql3']
[2023-07-16 02:50:08,716] {standard_task_runner.py:80} INFO - Job 897: Subtask cargar_data
[2023-07-16 02:50:08,803] {task_command.py:371} INFO - Running <TaskInstance: etl_api_marvel_hacia_aws_redshift_multitask.cargar_data manual__2023-07-16T02:50:00.771021+00:00 [running]> on host 7a1b6d75866e
[2023-07-16 02:50:08,900] {taskinstance.py:1591} INFO - Exporting the following env vars:
AIRFLOW_CTX_DAG_EMAIL=arielmfeldman.af@gmail.com
AIRFLOW_CTX_DAG_OWNER=Ariel Feldman
AIRFLOW_CTX_DAG_ID=etl_api_marvel_hacia_aws_redshift_multitask
AIRFLOW_CTX_TASK_ID=cargar_data
AIRFLOW_CTX_EXECUTION_DATE=2023-07-16T02:50:00.771021+00:00
AIRFLOW_CTX_TRY_NUMBER=1
AIRFLOW_CTX_DAG_RUN_ID=manual__2023-07-16T02:50:00.771021+00:00
[2023-07-16 02:50:08,917] {logging_mixin.py:115} INFO - Columnas en load data
[2023-07-16 02:50:08,918] {logging_mixin.py:115} INFO -  Index(['1', '2', '3', '4', '5', '6', '7', '8', '9', '10', '11', '12', '13',
       '14', '15', '16', '17', '18', '19', '20'],
      dtype='object')
[2023-07-16 02:50:11,060] {taskinstance.py:1909} ERROR - Task failed with exception
Traceback (most recent call last):
  File "/home/airflow/.local/lib/python3.7/site-packages/pandas/core/indexes/base.py", line 3361, in get_loc
    return self._engine.get_loc(casted_key)
  File "pandas/_libs/index.pyx", line 76, in pandas._libs.index.IndexEngine.get_loc
  File "pandas/_libs/index.pyx", line 108, in pandas._libs.index.IndexEngine.get_loc
  File "pandas/_libs/hashtable_class_helper.pxi", line 5198, in pandas._libs.hashtable.PyObjectHashTable.get_item
  File "pandas/_libs/hashtable_class_helper.pxi", line 5206, in pandas._libs.hashtable.PyObjectHashTable.get_item
KeyError: 'id_character'

The above exception was the direct cause of the following exception:

Traceback (most recent call last):
  File "/home/airflow/.local/lib/python3.7/site-packages/airflow/operators/python.py", line 171, in execute
    return_value = self.execute_callable()
  File "/home/airflow/.local/lib/python3.7/site-packages/airflow/operators/python.py", line 189, in execute_callable
    return self.python_callable(*self.op_args, **self.op_kwargs)
  File "/opt/airflow/dags/dag_etl_multiple_tasks.py", line 168, in load_data
    id_character =int(row['id_character'])
  File "/home/airflow/.local/lib/python3.7/site-packages/pandas/core/series.py", line 942, in __getitem__
    return self._get_value(key)
  File "/home/airflow/.local/lib/python3.7/site-packages/pandas/core/series.py", line 1051, in _get_value
    loc = self.index.get_loc(label)
  File "/home/airflow/.local/lib/python3.7/site-packages/pandas/core/indexes/base.py", line 3363, in get_loc
    raise KeyError(key) from err
KeyError: 'id_character'
[2023-07-16 02:50:11,073] {taskinstance.py:1420} INFO - Marking task as UP_FOR_RETRY. dag_id=etl_api_marvel_hacia_aws_redshift_multitask, task_id=cargar_data, execution_date=20230716T025000, start_date=20230716T025008, end_date=20230716T025011
[2023-07-16 02:50:11,093] {warnings.py:110} WARNING - /home/***/.local/lib/python3.7/site-packages/***/utils/email.py:119: PendingDeprecationWarning: Fetching SMTP credentials from configuration variables will be deprecated in a future release. Please set credentials using a connection instead.
  send_mime_email(e_from=mail_from, e_to=recipients, mime_msg=msg, conn_id=conn_id, dryrun=dryrun)

[2023-07-16 02:50:11,093] {configuration.py:552} WARNING - section/key [smtp/smtp_user] not found in config
[2023-07-16 02:50:11,093] {email.py:228} INFO - Email alerting: attempt 1
[2023-07-16 02:50:11,102] {configuration.py:552} WARNING - section/key [smtp/smtp_user] not found in config
[2023-07-16 02:50:11,103] {email.py:228} INFO - Email alerting: attempt 1
[2023-07-16 02:50:11,103] {taskinstance.py:1964} ERROR - Failed to send email to: ['arielmfeldman.af@gmail.com']
Traceback (most recent call last):
  File "/home/airflow/.local/lib/python3.7/site-packages/pandas/core/indexes/base.py", line 3361, in get_loc
    return self._engine.get_loc(casted_key)
  File "pandas/_libs/index.pyx", line 76, in pandas._libs.index.IndexEngine.get_loc
  File "pandas/_libs/index.pyx", line 108, in pandas._libs.index.IndexEngine.get_loc
  File "pandas/_libs/hashtable_class_helper.pxi", line 5198, in pandas._libs.hashtable.PyObjectHashTable.get_item
  File "pandas/_libs/hashtable_class_helper.pxi", line 5206, in pandas._libs.hashtable.PyObjectHashTable.get_item
KeyError: 'id_character'

The above exception was the direct cause of the following exception:

Traceback (most recent call last):
  File "/home/airflow/.local/lib/python3.7/site-packages/airflow/models/taskinstance.py", line 1471, in _run_raw_task
    self._execute_task_with_callbacks(context, test_mode)
  File "/home/airflow/.local/lib/python3.7/site-packages/airflow/models/taskinstance.py", line 1618, in _execute_task_with_callbacks
    result = self._execute_task(context, task_orig)
  File "/home/airflow/.local/lib/python3.7/site-packages/airflow/models/taskinstance.py", line 1679, in _execute_task
    result = execute_callable(context=context)
  File "/home/airflow/.local/lib/python3.7/site-packages/airflow/operators/python.py", line 171, in execute
    return_value = self.execute_callable()
  File "/home/airflow/.local/lib/python3.7/site-packages/airflow/operators/python.py", line 189, in execute_callable
    return self.python_callable(*self.op_args, **self.op_kwargs)
  File "/opt/airflow/dags/dag_etl_multiple_tasks.py", line 168, in load_data
    id_character =int(row['id_character'])
  File "/home/airflow/.local/lib/python3.7/site-packages/pandas/core/series.py", line 942, in __getitem__
    return self._get_value(key)
  File "/home/airflow/.local/lib/python3.7/site-packages/pandas/core/series.py", line 1051, in _get_value
    loc = self.index.get_loc(label)
  File "/home/airflow/.local/lib/python3.7/site-packages/pandas/core/indexes/base.py", line 3363, in get_loc
    raise KeyError(key) from err
KeyError: 'id_character'

During handling of the above exception, another exception occurred:

Traceback (most recent call last):
  File "/home/airflow/.local/lib/python3.7/site-packages/airflow/models/taskinstance.py", line 2346, in email_alert
    send_email(task.email, subject, html_content)
  File "/home/airflow/.local/lib/python3.7/site-packages/airflow/utils/email.py", line 71, in send_email
    **kwargs,
  File "/home/airflow/.local/lib/python3.7/site-packages/airflow/utils/email.py", line 119, in send_email_smtp
    send_mime_email(e_from=mail_from, e_to=recipients, mime_msg=msg, conn_id=conn_id, dryrun=dryrun)
  File "/home/airflow/.local/lib/python3.7/site-packages/airflow/utils/email.py", line 230, in send_mime_email
    smtp_conn = _get_smtp_connection(smtp_host, smtp_port, smtp_timeout, smtp_ssl)
  File "/home/airflow/.local/lib/python3.7/site-packages/airflow/utils/email.py", line 264, in _get_smtp_connection
    else smtplib.SMTP(host=host, port=port, timeout=timeout)
  File "/usr/local/lib/python3.7/smtplib.py", line 251, in __init__
    (code, msg) = self.connect(host, port)
  File "/usr/local/lib/python3.7/smtplib.py", line 336, in connect
    self.sock = self._get_socket(host, port, self.timeout)
  File "/usr/local/lib/python3.7/smtplib.py", line 307, in _get_socket
    self.source_address)
  File "/usr/local/lib/python3.7/socket.py", line 728, in create_connection
    raise err
  File "/usr/local/lib/python3.7/socket.py", line 716, in create_connection
    sock.connect(sa)
OSError: [Errno 99] Cannot assign requested address

During handling of the above exception, another exception occurred:

Traceback (most recent call last):
  File "/home/airflow/.local/lib/python3.7/site-packages/airflow/models/taskinstance.py", line 1962, in handle_failure
    self.email_alert(error, task)
  File "/home/airflow/.local/lib/python3.7/site-packages/airflow/models/taskinstance.py", line 2348, in email_alert
    send_email(task.email, subject, html_content_err)
  File "/home/airflow/.local/lib/python3.7/site-packages/airflow/utils/email.py", line 71, in send_email
    **kwargs,
  File "/home/airflow/.local/lib/python3.7/site-packages/airflow/utils/email.py", line 119, in send_email_smtp
    send_mime_email(e_from=mail_from, e_to=recipients, mime_msg=msg, conn_id=conn_id, dryrun=dryrun)
  File "/home/airflow/.local/lib/python3.7/site-packages/airflow/utils/email.py", line 230, in send_mime_email
    smtp_conn = _get_smtp_connection(smtp_host, smtp_port, smtp_timeout, smtp_ssl)
  File "/home/airflow/.local/lib/python3.7/site-packages/airflow/utils/email.py", line 264, in _get_smtp_connection
    else smtplib.SMTP(host=host, port=port, timeout=timeout)
  File "/usr/local/lib/python3.7/smtplib.py", line 251, in __init__
    (code, msg) = self.connect(host, port)
  File "/usr/local/lib/python3.7/smtplib.py", line 336, in connect
    self.sock = self._get_socket(host, port, self.timeout)
  File "/usr/local/lib/python3.7/smtplib.py", line 307, in _get_socket
    self.source_address)
  File "/usr/local/lib/python3.7/socket.py", line 728, in create_connection
    raise err
  File "/usr/local/lib/python3.7/socket.py", line 716, in create_connection
    sock.connect(sa)
OSError: [Errno 99] Cannot assign requested address
[2023-07-16 02:50:11,121] {standard_task_runner.py:97} ERROR - Failed to execute job 897 for task cargar_data ('id_character'; 10622)
[2023-07-16 02:50:11,133] {local_task_job.py:156} INFO - Task exited with return code 1
[2023-07-16 02:50:11,175] {local_task_job.py:273} INFO - 0 downstream tasks scheduled from follow-on schedule check
