[2023-07-16 02:41:55,884] {taskinstance.py:1179} INFO - Dependencies all met for <TaskInstance: etl_api_marvel_hacia_aws_redshift_multitask.cargar_data manual__2023-07-16T02:41:49.895785+00:00 [queued]>
[2023-07-16 02:41:55,899] {taskinstance.py:1179} INFO - Dependencies all met for <TaskInstance: etl_api_marvel_hacia_aws_redshift_multitask.cargar_data manual__2023-07-16T02:41:49.895785+00:00 [queued]>
[2023-07-16 02:41:55,899] {taskinstance.py:1376} INFO - 
--------------------------------------------------------------------------------
[2023-07-16 02:41:55,900] {taskinstance.py:1377} INFO - Starting attempt 1 of 11
[2023-07-16 02:41:55,900] {taskinstance.py:1378} INFO - 
--------------------------------------------------------------------------------
[2023-07-16 02:41:55,916] {taskinstance.py:1397} INFO - Executing <Task(PythonOperator): cargar_data> on 2023-07-16 02:41:49.895785+00:00
[2023-07-16 02:41:55,923] {standard_task_runner.py:52} INFO - Started process 10243 to run task
[2023-07-16 02:41:55,926] {standard_task_runner.py:79} INFO - Running: ['***', 'tasks', 'run', 'etl_api_marvel_hacia_aws_redshift_multitask', 'cargar_data', 'manual__2023-07-16T02:41:49.895785+00:00', '--job-id', '885', '--raw', '--subdir', 'DAGS_FOLDER/dag_etl_multiple_tasks.py', '--cfg-path', '/tmp/tmp5pysso0c', '--error-file', '/tmp/tmpzaz_1h7f']
[2023-07-16 02:41:55,928] {standard_task_runner.py:80} INFO - Job 885: Subtask cargar_data
[2023-07-16 02:41:55,998] {task_command.py:371} INFO - Running <TaskInstance: etl_api_marvel_hacia_aws_redshift_multitask.cargar_data manual__2023-07-16T02:41:49.895785+00:00 [running]> on host 7a1b6d75866e
[2023-07-16 02:41:56,158] {taskinstance.py:1591} INFO - Exporting the following env vars:
AIRFLOW_CTX_DAG_EMAIL=arielmfeldman.af@gmail.com
AIRFLOW_CTX_DAG_OWNER=Ariel Feldman
AIRFLOW_CTX_DAG_ID=etl_api_marvel_hacia_aws_redshift_multitask
AIRFLOW_CTX_TASK_ID=cargar_data
AIRFLOW_CTX_EXECUTION_DATE=2023-07-16T02:41:49.895785+00:00
AIRFLOW_CTX_TRY_NUMBER=1
AIRFLOW_CTX_DAG_RUN_ID=manual__2023-07-16T02:41:49.895785+00:00
[2023-07-16 02:41:56,192] {taskinstance.py:1909} ERROR - Task failed with exception
Traceback (most recent call last):
  File "/home/airflow/.local/lib/python3.7/site-packages/airflow/operators/python.py", line 171, in execute
    return_value = self.execute_callable()
  File "/home/airflow/.local/lib/python3.7/site-packages/airflow/operators/python.py", line 189, in execute_callable
    return self.python_callable(*self.op_args, **self.op_kwargs)
  File "/opt/airflow/dags/dag_etl_multiple_tasks.py", line 122, in load_data
    df = pd.DataFrame.from_dict(data,orient='index')
  File "/home/airflow/.local/lib/python3.7/site-packages/pandas/core/frame.py", line 1581, in from_dict
    if len(data) > 0:
TypeError: object of type 'NoneType' has no len()
[2023-07-16 02:41:56,239] {taskinstance.py:1420} INFO - Marking task as UP_FOR_RETRY. dag_id=etl_api_marvel_hacia_aws_redshift_multitask, task_id=cargar_data, execution_date=20230716T024149, start_date=20230716T024155, end_date=20230716T024156
[2023-07-16 02:41:56,266] {warnings.py:110} WARNING - /home/***/.local/lib/python3.7/site-packages/***/utils/email.py:119: PendingDeprecationWarning: Fetching SMTP credentials from configuration variables will be deprecated in a future release. Please set credentials using a connection instead.
  send_mime_email(e_from=mail_from, e_to=recipients, mime_msg=msg, conn_id=conn_id, dryrun=dryrun)

[2023-07-16 02:41:56,271] {configuration.py:552} WARNING - section/key [smtp/smtp_user] not found in config
[2023-07-16 02:41:56,271] {email.py:228} INFO - Email alerting: attempt 1
[2023-07-16 02:41:56,295] {configuration.py:552} WARNING - section/key [smtp/smtp_user] not found in config
[2023-07-16 02:41:56,296] {email.py:228} INFO - Email alerting: attempt 1
[2023-07-16 02:41:56,297] {taskinstance.py:1964} ERROR - Failed to send email to: ['arielmfeldman.af@gmail.com']
Traceback (most recent call last):
  File "/home/airflow/.local/lib/python3.7/site-packages/airflow/models/taskinstance.py", line 1471, in _run_raw_task
    self._execute_task_with_callbacks(context, test_mode)
  File "/home/airflow/.local/lib/python3.7/site-packages/airflow/models/taskinstance.py", line 1618, in _execute_task_with_callbacks
    result = self._execute_task(context, task_orig)
  File "/home/airflow/.local/lib/python3.7/site-packages/airflow/models/taskinstance.py", line 1679, in _execute_task
    result = execute_callable(context=context)
  File "/home/airflow/.local/lib/python3.7/site-packages/airflow/operators/python.py", line 171, in execute
    return_value = self.execute_callable()
  File "/home/airflow/.local/lib/python3.7/site-packages/airflow/operators/python.py", line 189, in execute_callable
    return self.python_callable(*self.op_args, **self.op_kwargs)
  File "/opt/airflow/dags/dag_etl_multiple_tasks.py", line 122, in load_data
    df = pd.DataFrame.from_dict(data,orient='index')
  File "/home/airflow/.local/lib/python3.7/site-packages/pandas/core/frame.py", line 1581, in from_dict
    if len(data) > 0:
TypeError: object of type 'NoneType' has no len()

During handling of the above exception, another exception occurred:

Traceback (most recent call last):
  File "/home/airflow/.local/lib/python3.7/site-packages/airflow/models/taskinstance.py", line 2346, in email_alert
    send_email(task.email, subject, html_content)
  File "/home/airflow/.local/lib/python3.7/site-packages/airflow/utils/email.py", line 71, in send_email
    **kwargs,
  File "/home/airflow/.local/lib/python3.7/site-packages/airflow/utils/email.py", line 119, in send_email_smtp
    send_mime_email(e_from=mail_from, e_to=recipients, mime_msg=msg, conn_id=conn_id, dryrun=dryrun)
  File "/home/airflow/.local/lib/python3.7/site-packages/airflow/utils/email.py", line 230, in send_mime_email
    smtp_conn = _get_smtp_connection(smtp_host, smtp_port, smtp_timeout, smtp_ssl)
  File "/home/airflow/.local/lib/python3.7/site-packages/airflow/utils/email.py", line 264, in _get_smtp_connection
    else smtplib.SMTP(host=host, port=port, timeout=timeout)
  File "/usr/local/lib/python3.7/smtplib.py", line 251, in __init__
    (code, msg) = self.connect(host, port)
  File "/usr/local/lib/python3.7/smtplib.py", line 336, in connect
    self.sock = self._get_socket(host, port, self.timeout)
  File "/usr/local/lib/python3.7/smtplib.py", line 307, in _get_socket
    self.source_address)
  File "/usr/local/lib/python3.7/socket.py", line 728, in create_connection
    raise err
  File "/usr/local/lib/python3.7/socket.py", line 716, in create_connection
    sock.connect(sa)
OSError: [Errno 99] Cannot assign requested address

During handling of the above exception, another exception occurred:

Traceback (most recent call last):
  File "/home/airflow/.local/lib/python3.7/site-packages/airflow/models/taskinstance.py", line 1962, in handle_failure
    self.email_alert(error, task)
  File "/home/airflow/.local/lib/python3.7/site-packages/airflow/models/taskinstance.py", line 2348, in email_alert
    send_email(task.email, subject, html_content_err)
  File "/home/airflow/.local/lib/python3.7/site-packages/airflow/utils/email.py", line 71, in send_email
    **kwargs,
  File "/home/airflow/.local/lib/python3.7/site-packages/airflow/utils/email.py", line 119, in send_email_smtp
    send_mime_email(e_from=mail_from, e_to=recipients, mime_msg=msg, conn_id=conn_id, dryrun=dryrun)
  File "/home/airflow/.local/lib/python3.7/site-packages/airflow/utils/email.py", line 230, in send_mime_email
    smtp_conn = _get_smtp_connection(smtp_host, smtp_port, smtp_timeout, smtp_ssl)
  File "/home/airflow/.local/lib/python3.7/site-packages/airflow/utils/email.py", line 264, in _get_smtp_connection
    else smtplib.SMTP(host=host, port=port, timeout=timeout)
  File "/usr/local/lib/python3.7/smtplib.py", line 251, in __init__
    (code, msg) = self.connect(host, port)
  File "/usr/local/lib/python3.7/smtplib.py", line 336, in connect
    self.sock = self._get_socket(host, port, self.timeout)
  File "/usr/local/lib/python3.7/smtplib.py", line 307, in _get_socket
    self.source_address)
  File "/usr/local/lib/python3.7/socket.py", line 728, in create_connection
    raise err
  File "/usr/local/lib/python3.7/socket.py", line 716, in create_connection
    sock.connect(sa)
OSError: [Errno 99] Cannot assign requested address
[2023-07-16 02:41:56,335] {standard_task_runner.py:97} ERROR - Failed to execute job 885 for task cargar_data (object of type 'NoneType' has no len(); 10243)
[2023-07-16 02:41:56,371] {local_task_job.py:156} INFO - Task exited with return code 1
[2023-07-16 02:41:56,435] {local_task_job.py:273} INFO - 0 downstream tasks scheduled from follow-on schedule check
