[2023-08-01 20:48:45,155] {taskinstance.py:1179} INFO - Dependencies all met for <TaskInstance: etl_api_marvel_hacia_aws_redshift_multitask.cargar_data scheduled__2023-08-01T20:27:41.077320+00:00 [queued]>
[2023-08-01 20:48:45,177] {taskinstance.py:1179} INFO - Dependencies all met for <TaskInstance: etl_api_marvel_hacia_aws_redshift_multitask.cargar_data scheduled__2023-08-01T20:27:41.077320+00:00 [queued]>
[2023-08-01 20:48:45,177] {taskinstance.py:1376} INFO - 
--------------------------------------------------------------------------------
[2023-08-01 20:48:45,177] {taskinstance.py:1377} INFO - Starting attempt 10 of 11
[2023-08-01 20:48:45,178] {taskinstance.py:1378} INFO - 
--------------------------------------------------------------------------------
[2023-08-01 20:48:45,215] {taskinstance.py:1397} INFO - Executing <Task(PythonOperator): cargar_data> on 2023-08-01 20:27:41.077320+00:00
[2023-08-01 20:48:45,225] {standard_task_runner.py:52} INFO - Started process 12772 to run task
[2023-08-01 20:48:45,233] {standard_task_runner.py:79} INFO - Running: ['***', 'tasks', 'run', 'etl_api_marvel_hacia_aws_redshift_multitask', 'cargar_data', 'scheduled__2023-08-01T20:27:41.077320+00:00', '--job-id', '1149', '--raw', '--subdir', 'DAGS_FOLDER/dag_etl_multiple_tasks_no_failure.py', '--cfg-path', '/tmp/tmpae06gc6j', '--error-file', '/tmp/tmp85mbauz8']
[2023-08-01 20:48:45,235] {standard_task_runner.py:80} INFO - Job 1149: Subtask cargar_data
[2023-08-01 20:48:45,381] {task_command.py:371} INFO - Running <TaskInstance: etl_api_marvel_hacia_aws_redshift_multitask.cargar_data scheduled__2023-08-01T20:27:41.077320+00:00 [running]> on host 24cbf2f01ed0
[2023-08-01 20:48:45,484] {taskinstance.py:1591} INFO - Exporting the following env vars:
AIRFLOW_CTX_DAG_EMAIL=arielmfeldman.af@gmail.com
AIRFLOW_CTX_DAG_OWNER=Ariel Feldman
AIRFLOW_CTX_DAG_ID=etl_api_marvel_hacia_aws_redshift_multitask
AIRFLOW_CTX_TASK_ID=cargar_data
AIRFLOW_CTX_EXECUTION_DATE=2023-08-01T20:27:41.077320+00:00
AIRFLOW_CTX_TRY_NUMBER=10
AIRFLOW_CTX_DAG_RUN_ID=scheduled__2023-08-01T20:27:41.077320+00:00
[2023-08-01 20:48:47,947] {taskinstance.py:1909} ERROR - Task failed with exception
Traceback (most recent call last):
  File "/home/airflow/.local/lib/python3.7/site-packages/redshift_connector/core.py", line 1631, in execute
    ps = cache["ps"][key]
KeyError: ('INSERT INTO arielmfeldman_coderhouse.marvelcharacters ("id_character","nombre","descripcion","cantidad_de_comics","cantidad_de_series","cantidad_de_historias","fecha_modificacion") VALUES(1011334,\'3-D Man\',\'Sin descripcion\', 12, 3, 21, \'2014-04-29\', \'2023-08-01\')', ())

During handling of the above exception, another exception occurred:

Traceback (most recent call last):
  File "/home/airflow/.local/lib/python3.7/site-packages/airflow/operators/python.py", line 171, in execute
    return_value = self.execute_callable()
  File "/home/airflow/.local/lib/python3.7/site-packages/airflow/operators/python.py", line 189, in execute_callable
    return self.python_callable(*self.op_args, **self.op_kwargs)
  File "/opt/airflow/dags/dag_etl_multiple_tasks_no_failure.py", line 256, in load_data
    cursor.execute(insert+values)
  File "/home/airflow/.local/lib/python3.7/site-packages/redshift_connector/cursor.py", line 240, in execute
    self._c.execute(self, operation, args)
  File "/home/airflow/.local/lib/python3.7/site-packages/redshift_connector/core.py", line 1701, in execute
    self.handle_messages(cursor)
  File "/home/airflow/.local/lib/python3.7/site-packages/redshift_connector/core.py", line 1969, in handle_messages
    raise self.error
redshift_connector.error.ProgrammingError: {'S': 'ERROR', 'C': '42601', 'M': 'INSERT has more expressions than target columns', 'F': '../src/pg/src/backend/parser/parser_analyze.c', 'L': '3081', 'R': 'transformInsertStmt'}
[2023-08-01 20:48:47,968] {taskinstance.py:1420} INFO - Marking task as UP_FOR_RETRY. dag_id=etl_api_marvel_hacia_aws_redshift_multitask, task_id=cargar_data, execution_date=20230801T202741, start_date=20230801T204845, end_date=20230801T204847
[2023-08-01 20:48:48,029] {warnings.py:110} WARNING - /home/***/.local/lib/python3.7/site-packages/***/utils/email.py:119: PendingDeprecationWarning: Fetching SMTP credentials from configuration variables will be deprecated in a future release. Please set credentials using a connection instead.
  send_mime_email(e_from=mail_from, e_to=recipients, mime_msg=msg, conn_id=conn_id, dryrun=dryrun)

[2023-08-01 20:48:48,029] {configuration.py:552} WARNING - section/key [smtp/smtp_user] not found in config
[2023-08-01 20:48:48,029] {email.py:228} INFO - Email alerting: attempt 1
[2023-08-01 20:48:48,050] {configuration.py:552} WARNING - section/key [smtp/smtp_user] not found in config
[2023-08-01 20:48:48,050] {email.py:228} INFO - Email alerting: attempt 1
[2023-08-01 20:48:48,055] {taskinstance.py:1964} ERROR - Failed to send email to: ['arielmfeldman.af@gmail.com']
Traceback (most recent call last):
  File "/home/airflow/.local/lib/python3.7/site-packages/redshift_connector/core.py", line 1631, in execute
    ps = cache["ps"][key]
KeyError: ('INSERT INTO arielmfeldman_coderhouse.marvelcharacters ("id_character","nombre","descripcion","cantidad_de_comics","cantidad_de_series","cantidad_de_historias","fecha_modificacion") VALUES(1011334,\'3-D Man\',\'Sin descripcion\', 12, 3, 21, \'2014-04-29\', \'2023-08-01\')', ())

During handling of the above exception, another exception occurred:

Traceback (most recent call last):
  File "/home/airflow/.local/lib/python3.7/site-packages/airflow/models/taskinstance.py", line 1471, in _run_raw_task
    self._execute_task_with_callbacks(context, test_mode)
  File "/home/airflow/.local/lib/python3.7/site-packages/airflow/models/taskinstance.py", line 1618, in _execute_task_with_callbacks
    result = self._execute_task(context, task_orig)
  File "/home/airflow/.local/lib/python3.7/site-packages/airflow/models/taskinstance.py", line 1679, in _execute_task
    result = execute_callable(context=context)
  File "/home/airflow/.local/lib/python3.7/site-packages/airflow/operators/python.py", line 171, in execute
    return_value = self.execute_callable()
  File "/home/airflow/.local/lib/python3.7/site-packages/airflow/operators/python.py", line 189, in execute_callable
    return self.python_callable(*self.op_args, **self.op_kwargs)
  File "/opt/airflow/dags/dag_etl_multiple_tasks_no_failure.py", line 256, in load_data
    cursor.execute(insert+values)
  File "/home/airflow/.local/lib/python3.7/site-packages/redshift_connector/cursor.py", line 240, in execute
    self._c.execute(self, operation, args)
  File "/home/airflow/.local/lib/python3.7/site-packages/redshift_connector/core.py", line 1701, in execute
    self.handle_messages(cursor)
  File "/home/airflow/.local/lib/python3.7/site-packages/redshift_connector/core.py", line 1969, in handle_messages
    raise self.error
redshift_connector.error.ProgrammingError: {'S': 'ERROR', 'C': '42601', 'M': 'INSERT has more expressions than target columns', 'F': '../src/pg/src/backend/parser/parser_analyze.c', 'L': '3081', 'R': 'transformInsertStmt'}

During handling of the above exception, another exception occurred:

Traceback (most recent call last):
  File "/home/airflow/.local/lib/python3.7/site-packages/airflow/models/taskinstance.py", line 2346, in email_alert
    send_email(task.email, subject, html_content)
  File "/home/airflow/.local/lib/python3.7/site-packages/airflow/utils/email.py", line 71, in send_email
    **kwargs,
  File "/home/airflow/.local/lib/python3.7/site-packages/airflow/utils/email.py", line 119, in send_email_smtp
    send_mime_email(e_from=mail_from, e_to=recipients, mime_msg=msg, conn_id=conn_id, dryrun=dryrun)
  File "/home/airflow/.local/lib/python3.7/site-packages/airflow/utils/email.py", line 230, in send_mime_email
    smtp_conn = _get_smtp_connection(smtp_host, smtp_port, smtp_timeout, smtp_ssl)
  File "/home/airflow/.local/lib/python3.7/site-packages/airflow/utils/email.py", line 264, in _get_smtp_connection
    else smtplib.SMTP(host=host, port=port, timeout=timeout)
  File "/usr/local/lib/python3.7/smtplib.py", line 251, in __init__
    (code, msg) = self.connect(host, port)
  File "/usr/local/lib/python3.7/smtplib.py", line 336, in connect
    self.sock = self._get_socket(host, port, self.timeout)
  File "/usr/local/lib/python3.7/smtplib.py", line 307, in _get_socket
    self.source_address)
  File "/usr/local/lib/python3.7/socket.py", line 728, in create_connection
    raise err
  File "/usr/local/lib/python3.7/socket.py", line 716, in create_connection
    sock.connect(sa)
OSError: [Errno 99] Cannot assign requested address

During handling of the above exception, another exception occurred:

Traceback (most recent call last):
  File "/home/airflow/.local/lib/python3.7/site-packages/airflow/models/taskinstance.py", line 1962, in handle_failure
    self.email_alert(error, task)
  File "/home/airflow/.local/lib/python3.7/site-packages/airflow/models/taskinstance.py", line 2348, in email_alert
    send_email(task.email, subject, html_content_err)
  File "/home/airflow/.local/lib/python3.7/site-packages/airflow/utils/email.py", line 71, in send_email
    **kwargs,
  File "/home/airflow/.local/lib/python3.7/site-packages/airflow/utils/email.py", line 119, in send_email_smtp
    send_mime_email(e_from=mail_from, e_to=recipients, mime_msg=msg, conn_id=conn_id, dryrun=dryrun)
  File "/home/airflow/.local/lib/python3.7/site-packages/airflow/utils/email.py", line 230, in send_mime_email
    smtp_conn = _get_smtp_connection(smtp_host, smtp_port, smtp_timeout, smtp_ssl)
  File "/home/airflow/.local/lib/python3.7/site-packages/airflow/utils/email.py", line 264, in _get_smtp_connection
    else smtplib.SMTP(host=host, port=port, timeout=timeout)
  File "/usr/local/lib/python3.7/smtplib.py", line 251, in __init__
    (code, msg) = self.connect(host, port)
  File "/usr/local/lib/python3.7/smtplib.py", line 336, in connect
    self.sock = self._get_socket(host, port, self.timeout)
  File "/usr/local/lib/python3.7/smtplib.py", line 307, in _get_socket
    self.source_address)
  File "/usr/local/lib/python3.7/socket.py", line 728, in create_connection
    raise err
  File "/usr/local/lib/python3.7/socket.py", line 716, in create_connection
    sock.connect(sa)
OSError: [Errno 99] Cannot assign requested address
[2023-08-01 20:48:48,089] {standard_task_runner.py:97} ERROR - Failed to execute job 1149 for task cargar_data ({'S': 'ERROR', 'C': '42601', 'M': 'INSERT has more expressions than target columns', 'F': '../src/pg/src/backend/parser/parser_analyze.c', 'L': '3081', 'R': 'transformInsertStmt'}; 12772)
[2023-08-01 20:48:48,159] {local_task_job.py:156} INFO - Task exited with return code 1
[2023-08-01 20:48:48,238] {local_task_job.py:273} INFO - 0 downstream tasks scheduled from follow-on schedule check
