[2023-07-16 02:32:01,163] {taskinstance.py:1179} INFO - Dependencies all met for <TaskInstance: etl_api_marvel_hacia_aws_redshift_multitask.transformar manual__2023-07-16T02:23:49.944661+00:00 [queued]>
[2023-07-16 02:32:01,178] {taskinstance.py:1179} INFO - Dependencies all met for <TaskInstance: etl_api_marvel_hacia_aws_redshift_multitask.transformar manual__2023-07-16T02:23:49.944661+00:00 [queued]>
[2023-07-16 02:32:01,178] {taskinstance.py:1376} INFO - 
--------------------------------------------------------------------------------
[2023-07-16 02:32:01,178] {taskinstance.py:1377} INFO - Starting attempt 5 of 11
[2023-07-16 02:32:01,178] {taskinstance.py:1378} INFO - 
--------------------------------------------------------------------------------
[2023-07-16 02:32:01,203] {taskinstance.py:1397} INFO - Executing <Task(PythonOperator): transformar> on 2023-07-16 02:23:49.944661+00:00
[2023-07-16 02:32:01,210] {standard_task_runner.py:52} INFO - Started process 9811 to run task
[2023-07-16 02:32:01,214] {standard_task_runner.py:79} INFO - Running: ['***', 'tasks', 'run', 'etl_api_marvel_hacia_aws_redshift_multitask', 'transformar', 'manual__2023-07-16T02:23:49.944661+00:00', '--job-id', '869', '--raw', '--subdir', 'DAGS_FOLDER/dag_etl_multiple_tasks.py', '--cfg-path', '/tmp/tmp9qamef54', '--error-file', '/tmp/tmp215oj48e']
[2023-07-16 02:32:01,216] {standard_task_runner.py:80} INFO - Job 869: Subtask transformar
[2023-07-16 02:32:01,303] {task_command.py:371} INFO - Running <TaskInstance: etl_api_marvel_hacia_aws_redshift_multitask.transformar manual__2023-07-16T02:23:49.944661+00:00 [running]> on host 7a1b6d75866e
[2023-07-16 02:32:01,514] {taskinstance.py:1591} INFO - Exporting the following env vars:
AIRFLOW_CTX_DAG_EMAIL=arielmfeldman.af@gmail.com
AIRFLOW_CTX_DAG_OWNER=Ariel Feldman
AIRFLOW_CTX_DAG_ID=etl_api_marvel_hacia_aws_redshift_multitask
AIRFLOW_CTX_TASK_ID=transformar
AIRFLOW_CTX_EXECUTION_DATE=2023-07-16T02:23:49.944661+00:00
AIRFLOW_CTX_TRY_NUMBER=5
AIRFLOW_CTX_DAG_RUN_ID=manual__2023-07-16T02:23:49.944661+00:00
[2023-07-16 02:32:01,549] {taskinstance.py:1909} ERROR - Task failed with exception
Traceback (most recent call last):
  File "/home/airflow/.local/lib/python3.7/site-packages/airflow/operators/python.py", line 171, in execute
    return_value = self.execute_callable()
  File "/home/airflow/.local/lib/python3.7/site-packages/airflow/operators/python.py", line 189, in execute_callable
    return self.python_callable(*self.op_args, **self.op_kwargs)
  File "/opt/airflow/dags/dag_etl_multiple_tasks.py", line 89, in transform
    print(registros[0])
TypeError: 'NoneType' object is not subscriptable
[2023-07-16 02:32:01,566] {taskinstance.py:1420} INFO - Marking task as UP_FOR_RETRY. dag_id=etl_api_marvel_hacia_aws_redshift_multitask, task_id=transformar, execution_date=20230716T022349, start_date=20230716T023201, end_date=20230716T023201
[2023-07-16 02:32:01,595] {warnings.py:110} WARNING - /home/***/.local/lib/python3.7/site-packages/***/utils/email.py:119: PendingDeprecationWarning: Fetching SMTP credentials from configuration variables will be deprecated in a future release. Please set credentials using a connection instead.
  send_mime_email(e_from=mail_from, e_to=recipients, mime_msg=msg, conn_id=conn_id, dryrun=dryrun)

[2023-07-16 02:32:01,595] {configuration.py:552} WARNING - section/key [smtp/smtp_user] not found in config
[2023-07-16 02:32:01,595] {email.py:228} INFO - Email alerting: attempt 1
[2023-07-16 02:32:01,611] {configuration.py:552} WARNING - section/key [smtp/smtp_user] not found in config
[2023-07-16 02:32:01,611] {email.py:228} INFO - Email alerting: attempt 1
[2023-07-16 02:32:01,612] {taskinstance.py:1964} ERROR - Failed to send email to: ['arielmfeldman.af@gmail.com']
Traceback (most recent call last):
  File "/home/airflow/.local/lib/python3.7/site-packages/airflow/models/taskinstance.py", line 1471, in _run_raw_task
    self._execute_task_with_callbacks(context, test_mode)
  File "/home/airflow/.local/lib/python3.7/site-packages/airflow/models/taskinstance.py", line 1618, in _execute_task_with_callbacks
    result = self._execute_task(context, task_orig)
  File "/home/airflow/.local/lib/python3.7/site-packages/airflow/models/taskinstance.py", line 1679, in _execute_task
    result = execute_callable(context=context)
  File "/home/airflow/.local/lib/python3.7/site-packages/airflow/operators/python.py", line 171, in execute
    return_value = self.execute_callable()
  File "/home/airflow/.local/lib/python3.7/site-packages/airflow/operators/python.py", line 189, in execute_callable
    return self.python_callable(*self.op_args, **self.op_kwargs)
  File "/opt/airflow/dags/dag_etl_multiple_tasks.py", line 89, in transform
    print(registros[0])
TypeError: 'NoneType' object is not subscriptable

During handling of the above exception, another exception occurred:

Traceback (most recent call last):
  File "/home/airflow/.local/lib/python3.7/site-packages/airflow/models/taskinstance.py", line 2346, in email_alert
    send_email(task.email, subject, html_content)
  File "/home/airflow/.local/lib/python3.7/site-packages/airflow/utils/email.py", line 71, in send_email
    **kwargs,
  File "/home/airflow/.local/lib/python3.7/site-packages/airflow/utils/email.py", line 119, in send_email_smtp
    send_mime_email(e_from=mail_from, e_to=recipients, mime_msg=msg, conn_id=conn_id, dryrun=dryrun)
  File "/home/airflow/.local/lib/python3.7/site-packages/airflow/utils/email.py", line 230, in send_mime_email
    smtp_conn = _get_smtp_connection(smtp_host, smtp_port, smtp_timeout, smtp_ssl)
  File "/home/airflow/.local/lib/python3.7/site-packages/airflow/utils/email.py", line 264, in _get_smtp_connection
    else smtplib.SMTP(host=host, port=port, timeout=timeout)
  File "/usr/local/lib/python3.7/smtplib.py", line 251, in __init__
    (code, msg) = self.connect(host, port)
  File "/usr/local/lib/python3.7/smtplib.py", line 336, in connect
    self.sock = self._get_socket(host, port, self.timeout)
  File "/usr/local/lib/python3.7/smtplib.py", line 307, in _get_socket
    self.source_address)
  File "/usr/local/lib/python3.7/socket.py", line 728, in create_connection
    raise err
  File "/usr/local/lib/python3.7/socket.py", line 716, in create_connection
    sock.connect(sa)
OSError: [Errno 99] Cannot assign requested address

During handling of the above exception, another exception occurred:

Traceback (most recent call last):
  File "/home/airflow/.local/lib/python3.7/site-packages/airflow/models/taskinstance.py", line 1962, in handle_failure
    self.email_alert(error, task)
  File "/home/airflow/.local/lib/python3.7/site-packages/airflow/models/taskinstance.py", line 2348, in email_alert
    send_email(task.email, subject, html_content_err)
  File "/home/airflow/.local/lib/python3.7/site-packages/airflow/utils/email.py", line 71, in send_email
    **kwargs,
  File "/home/airflow/.local/lib/python3.7/site-packages/airflow/utils/email.py", line 119, in send_email_smtp
    send_mime_email(e_from=mail_from, e_to=recipients, mime_msg=msg, conn_id=conn_id, dryrun=dryrun)
  File "/home/airflow/.local/lib/python3.7/site-packages/airflow/utils/email.py", line 230, in send_mime_email
    smtp_conn = _get_smtp_connection(smtp_host, smtp_port, smtp_timeout, smtp_ssl)
  File "/home/airflow/.local/lib/python3.7/site-packages/airflow/utils/email.py", line 264, in _get_smtp_connection
    else smtplib.SMTP(host=host, port=port, timeout=timeout)
  File "/usr/local/lib/python3.7/smtplib.py", line 251, in __init__
    (code, msg) = self.connect(host, port)
  File "/usr/local/lib/python3.7/smtplib.py", line 336, in connect
    self.sock = self._get_socket(host, port, self.timeout)
  File "/usr/local/lib/python3.7/smtplib.py", line 307, in _get_socket
    self.source_address)
  File "/usr/local/lib/python3.7/socket.py", line 728, in create_connection
    raise err
  File "/usr/local/lib/python3.7/socket.py", line 716, in create_connection
    sock.connect(sa)
OSError: [Errno 99] Cannot assign requested address
[2023-07-16 02:32:01,640] {standard_task_runner.py:97} ERROR - Failed to execute job 869 for task transformar ('NoneType' object is not subscriptable; 9811)
[2023-07-16 02:32:01,686] {local_task_job.py:156} INFO - Task exited with return code 1
[2023-07-16 02:32:01,875] {local_task_job.py:273} INFO - 0 downstream tasks scheduled from follow-on schedule check
