[2023-08-01 22:43:28,377] {taskinstance.py:1179} INFO - Dependencies all met for <TaskInstance: etl_api_marvel.extract manual__2023-08-01T22:43:03.615826+00:00 [queued]>
[2023-08-01 22:43:28,391] {taskinstance.py:1179} INFO - Dependencies all met for <TaskInstance: etl_api_marvel.extract manual__2023-08-01T22:43:03.615826+00:00 [queued]>
[2023-08-01 22:43:28,391] {taskinstance.py:1376} INFO - 
--------------------------------------------------------------------------------
[2023-08-01 22:43:28,391] {taskinstance.py:1377} INFO - Starting attempt 2 of 2
[2023-08-01 22:43:28,391] {taskinstance.py:1378} INFO - 
--------------------------------------------------------------------------------
[2023-08-01 22:43:28,410] {taskinstance.py:1397} INFO - Executing <Task(PythonOperator): extract> on 2023-08-01 22:43:03.615826+00:00
[2023-08-01 22:43:28,419] {standard_task_runner.py:52} INFO - Started process 145 to run task
[2023-08-01 22:43:28,424] {standard_task_runner.py:79} INFO - Running: ['***', 'tasks', 'run', 'etl_api_marvel', 'extract', 'manual__2023-08-01T22:43:03.615826+00:00', '--job-id', '1238', '--raw', '--subdir', 'DAGS_FOLDER/dag_etl_multiple_tasks_failure.py', '--cfg-path', '/tmp/tmppwg25dyj', '--error-file', '/tmp/tmpcu21cc14']
[2023-08-01 22:43:28,425] {standard_task_runner.py:80} INFO - Job 1238: Subtask extract
[2023-08-01 22:43:28,510] {task_command.py:371} INFO - Running <TaskInstance: etl_api_marvel.extract manual__2023-08-01T22:43:03.615826+00:00 [running]> on host 24cbf2f01ed0
[2023-08-01 22:43:28,614] {taskinstance.py:1591} INFO - Exporting the following env vars:
AIRFLOW_CTX_DAG_EMAIL=arielmfeldman.af@gmail.com
AIRFLOW_CTX_DAG_OWNER=Ariel Feldman
AIRFLOW_CTX_DAG_ID=etl_api_marvel
AIRFLOW_CTX_TASK_ID=extract
AIRFLOW_CTX_EXECUTION_DATE=2023-08-01T22:43:03.615826+00:00
AIRFLOW_CTX_TRY_NUMBER=2
AIRFLOW_CTX_DAG_RUN_ID=manual__2023-08-01T22:43:03.615826+00:00
[2023-08-01 22:43:28,615] {taskinstance.py:1909} ERROR - Task failed with exception
Traceback (most recent call last):
  File "/home/airflow/.local/lib/python3.7/site-packages/airflow/operators/python.py", line 171, in execute
    return_value = self.execute_callable()
  File "/home/airflow/.local/lib/python3.7/site-packages/airflow/operators/python.py", line 189, in execute_callable
    return self.python_callable(*self.op_args, **self.op_kwargs)
  File "/opt/airflow/dags/dag_etl_multiple_tasks_failure.py", line 155, in extract_data
    response = requests.get(marvel_var['SECRET_URL_API_MARVEL'])
NameError: name 'marvel_var' is not defined
[2023-08-01 22:43:28,629] {taskinstance.py:1420} INFO - Marking task as FAILED. dag_id=etl_api_marvel, task_id=extract, execution_date=20230801T224303, start_date=20230801T224328, end_date=20230801T224328
[2023-08-01 22:43:28,646] {warnings.py:110} WARNING - /home/***/.local/lib/python3.7/site-packages/***/utils/email.py:119: PendingDeprecationWarning: Fetching SMTP credentials from configuration variables will be deprecated in a future release. Please set credentials using a connection instead.
  send_mime_email(e_from=mail_from, e_to=recipients, mime_msg=msg, conn_id=conn_id, dryrun=dryrun)

[2023-08-01 22:43:28,647] {configuration.py:552} WARNING - section/key [smtp/smtp_user] not found in config
[2023-08-01 22:43:28,647] {email.py:228} INFO - Email alerting: attempt 1
[2023-08-01 22:43:28,655] {configuration.py:552} WARNING - section/key [smtp/smtp_user] not found in config
[2023-08-01 22:43:28,656] {email.py:228} INFO - Email alerting: attempt 1
[2023-08-01 22:43:28,656] {taskinstance.py:1964} ERROR - Failed to send email to: ['arielmfeldman.af@gmail.com']
Traceback (most recent call last):
  File "/home/airflow/.local/lib/python3.7/site-packages/airflow/models/taskinstance.py", line 1471, in _run_raw_task
    self._execute_task_with_callbacks(context, test_mode)
  File "/home/airflow/.local/lib/python3.7/site-packages/airflow/models/taskinstance.py", line 1618, in _execute_task_with_callbacks
    result = self._execute_task(context, task_orig)
  File "/home/airflow/.local/lib/python3.7/site-packages/airflow/models/taskinstance.py", line 1679, in _execute_task
    result = execute_callable(context=context)
  File "/home/airflow/.local/lib/python3.7/site-packages/airflow/operators/python.py", line 171, in execute
    return_value = self.execute_callable()
  File "/home/airflow/.local/lib/python3.7/site-packages/airflow/operators/python.py", line 189, in execute_callable
    return self.python_callable(*self.op_args, **self.op_kwargs)
  File "/opt/airflow/dags/dag_etl_multiple_tasks_failure.py", line 155, in extract_data
    response = requests.get(marvel_var['SECRET_URL_API_MARVEL'])
NameError: name 'marvel_var' is not defined

During handling of the above exception, another exception occurred:

Traceback (most recent call last):
  File "/home/airflow/.local/lib/python3.7/site-packages/airflow/models/taskinstance.py", line 2346, in email_alert
    send_email(task.email, subject, html_content)
  File "/home/airflow/.local/lib/python3.7/site-packages/airflow/utils/email.py", line 71, in send_email
    **kwargs,
  File "/home/airflow/.local/lib/python3.7/site-packages/airflow/utils/email.py", line 119, in send_email_smtp
    send_mime_email(e_from=mail_from, e_to=recipients, mime_msg=msg, conn_id=conn_id, dryrun=dryrun)
  File "/home/airflow/.local/lib/python3.7/site-packages/airflow/utils/email.py", line 230, in send_mime_email
    smtp_conn = _get_smtp_connection(smtp_host, smtp_port, smtp_timeout, smtp_ssl)
  File "/home/airflow/.local/lib/python3.7/site-packages/airflow/utils/email.py", line 264, in _get_smtp_connection
    else smtplib.SMTP(host=host, port=port, timeout=timeout)
  File "/usr/local/lib/python3.7/smtplib.py", line 251, in __init__
    (code, msg) = self.connect(host, port)
  File "/usr/local/lib/python3.7/smtplib.py", line 336, in connect
    self.sock = self._get_socket(host, port, self.timeout)
  File "/usr/local/lib/python3.7/smtplib.py", line 307, in _get_socket
    self.source_address)
  File "/usr/local/lib/python3.7/socket.py", line 728, in create_connection
    raise err
  File "/usr/local/lib/python3.7/socket.py", line 716, in create_connection
    sock.connect(sa)
OSError: [Errno 99] Cannot assign requested address

During handling of the above exception, another exception occurred:

Traceback (most recent call last):
  File "/home/airflow/.local/lib/python3.7/site-packages/airflow/models/taskinstance.py", line 1962, in handle_failure
    self.email_alert(error, task)
  File "/home/airflow/.local/lib/python3.7/site-packages/airflow/models/taskinstance.py", line 2348, in email_alert
    send_email(task.email, subject, html_content_err)
  File "/home/airflow/.local/lib/python3.7/site-packages/airflow/utils/email.py", line 71, in send_email
    **kwargs,
  File "/home/airflow/.local/lib/python3.7/site-packages/airflow/utils/email.py", line 119, in send_email_smtp
    send_mime_email(e_from=mail_from, e_to=recipients, mime_msg=msg, conn_id=conn_id, dryrun=dryrun)
  File "/home/airflow/.local/lib/python3.7/site-packages/airflow/utils/email.py", line 230, in send_mime_email
    smtp_conn = _get_smtp_connection(smtp_host, smtp_port, smtp_timeout, smtp_ssl)
  File "/home/airflow/.local/lib/python3.7/site-packages/airflow/utils/email.py", line 264, in _get_smtp_connection
    else smtplib.SMTP(host=host, port=port, timeout=timeout)
  File "/usr/local/lib/python3.7/smtplib.py", line 251, in __init__
    (code, msg) = self.connect(host, port)
  File "/usr/local/lib/python3.7/smtplib.py", line 336, in connect
    self.sock = self._get_socket(host, port, self.timeout)
  File "/usr/local/lib/python3.7/smtplib.py", line 307, in _get_socket
    self.source_address)
  File "/usr/local/lib/python3.7/socket.py", line 728, in create_connection
    raise err
  File "/usr/local/lib/python3.7/socket.py", line 716, in create_connection
    sock.connect(sa)
OSError: [Errno 99] Cannot assign requested address
[2023-08-01 22:43:28,674] {standard_task_runner.py:97} ERROR - Failed to execute job 1238 for task extract (name 'marvel_var' is not defined; 145)
[2023-08-01 22:43:28,715] {local_task_job.py:156} INFO - Task exited with return code 1
[2023-08-01 22:43:31,599] {local_task_job.py:273} INFO - 0 downstream tasks scheduled from follow-on schedule check
